Workbook

Sheet Instructions
A1: S3 / Glacier Deal Intake Template
A3: General Guidance
A4: 1. This intake template is intended to be used for ALL custom S3/Glacier deals. PARCs are excluded from requiring an intake form
A5: 2. The excel should be added as an attachment to storage custom deal approval request in the tool by SCE/WWPS while raising a storage custom deal request. This is an addition to the approval template and does not replace it
A6: 3. The given template is only for S3/Glacier storage custom deal intake qualification. Private pricing requests for EC2/EBS/networking custom deals etc, are NOT covered under this intake form
A8: Instructions
A9: 1. All tabs will be filled by account teams and provided to SCE/WWPS. The SCE/WWPS team will then qualify the inputs before submitting the template as part of approval request
A10: 2. The inputs of the intake form are intended to support comprehensive deal qualification. We recommend the intake form be filled duly to avoid request rejection.
A12: Helpful Links
A13: Pre-Approved Rate Cards
A14: Storage Classes
A15: Use Cases for Glacier Storage Classes
... A17: Please email s3parc@amazon.com for any further questions/concerns.

Sheet Data Ramp Plan
B3: BJS or ZHY | C3: Unit Price
B4: Data in PB | C4: PTS on Jan 22
B5: Tier | D5: 45839 | E5: 45870 | F5: 45901 | G5: 45931 | H5: 45962 | I5: 45992 | J5: 46023 | K5: 46054 | L5: 46082 | M5: 46113 | N5: 46143 | O5: 46174 | P5: 46204 | Q5: 46235 | R5: 46266 | S5: 46296 | T5: 46327 | U5: 46357 | V5: 46388 | W5: 46419 | X5: 46447 | Y5: 46478 | Z5: 46508 | AA5: 46539 | AB5: 46569 | AC5: 46600 | AD5: 46631 | AE5: 46661 | AF5: 46692 | AG5: 46722 | AH5: 46753 | AI5: 46784 | AJ5: 46813 | AK5: 46844 | AL5: 46874 | AM5: 46905
B6: S3 Standard | C6: 0.00451 | D6: =D8*0.3 -> 15 | E6: =E8*0.3 -> 30 | F6: =F8*0.3 -> 45 | G6: =G8*0.3 -> 60 | H6: =H8*0.3 -> 75 | I6: =I8*0.3 -> 90 | J6: =J8*0.3 -> 90 | K6: =K8*0.3 -> 90 | ... AM6: =AM8*0.3 -> 90
B7: S-IA | C7: 0.00191 | D7: =D8*0.7 -> 35 | E7: =E8*0.7 -> 70 | F7: =F8*0.7 -> 105 | G7: =G8*0.7 -> 140 | H7: =H8*0.7 -> 175 | I7: =I8*0.7 -> 210 | J7: =J8*0.7 -> 210 | K7: =K8*0.7 -> 210 | ... AM7: =AM8*0.7 -> 210
B8: Total | D8: 50 | E8: 100 | F8: 150 | G8: 200 | H8: 250 | I8: 300 | J8: 300 | K8: 300 | L8: 300 | M8: 300 | N8: 300 | O8: 300 | P8: 300 | Q8: 300 | R8: 300 | S8: 300 | T8: 300 | U8: 300 | V8: 300 | W8: 300 | X8: 300 | Y8: 300 | Z8: 300 | AA8: 300 | AB8: 300 | AC8: 300 | AD8: 300 | AE8: 300 | AF8: 300 | AG8: 300 | AH8: 300 | AI8: 300 | AJ8: 300 | AK8: 300 | AL8: 300 | AM8: 300
B10: S3 STD
B11: PUT | C11: 8.1355932e-05 | D11: =D13/$C$54*1024 -> 6442450944 | E11: =E13/$C$54*1024 -> 6442450944 | F11: =F13/$C$54*1024 -> 6442450944 | G11: =G13/$C$54*1024 -> 6442450944 | H11: =H13/$C$54*1024 -> 6442450944 | I11: =I13/$C$54*1024 -> 6442450944 | J11: =$C55*1000*60*60*730*$C$58/100*$J$6 -> 4443619500 | K11: =$C55*1000*60*60*730*$C$58/100*$J$6 -> 4443619500 | L11: =$C55*1000*60*60*730*$C$58/100*$J$6 -> 4443619500 | M11: =$C55*1000*60*60*730*$C$58/100*$J$6 -> 4443619500 | N11: =$C55*1000*60*60*730*$C$58/100*$J$6 -> 4443619500 | O11: =$C55*1000*60*60*730*$C$58/100*$J$6 -> 4443619500 | P11: =$C55*1000*60*60*730*$C$58/100*$J$6 -> 4443619500 | Q11: =$C55*1000*60*60*730*$C$58/100*$J$6 -> 4443619500 | ... AG11: =$C55*1000*60*60*730*$C$58/100*$J$6 -> 4443619500
B12: GET | C12: 0.00050847458 | D12: =D14/$C$54*1024 -> 6.4424509e+08 | E12: =E14/$C$54*1024 -> 6.4424509e+08 | F12: =F14/$C$54*1024 -> 6.4424509e+08 | G12: =G14/$C$54*1024 -> 6.4424509e+08 | H12: =H14/$C$54*1024 -> 6.4424509e+08 | I12: =I14/$C$54*1024 -> 6.4424509e+08 | J12: =$C56*1000*60*60*730*$C$58/100*$J$6 -> 5332343400 | K12: =$C56*1000*60*60*730*$C$58/100*$J$6 -> 5332343400 | L12: =$C56*1000*60*60*730*$C$58/100*$J$6 -> 5332343400 | M12: =$C56*1000*60*60*730*$C$58/100*$J$6 -> 5332343400 | N12: =$C56*1000*60*60*730*$C$58/100*$J$6 -> 5332343400 | O12: =$C56*1000*60*60*730*$C$58/100*$J$6 -> 5332343400 | P12: =$C56*1000*60*60*730*$C$58/100*$J$6 -> 5332343400 | Q12: =$C56*1000*60*60*730*$C$58/100*$J$6 -> 5332343400 | ... AG12: =$C56*1000*60*60*730*$C$58/100*$J$6 -> 5332343400
B13: DTI (GB) | D13: =D6*1024*1024 -> 15728640 | E13: =(E6-D6)*1024*1024 -> 15728640 | F13: =(F6-E6)*1024*1024 -> 15728640 | G13: =(G6-F6)*1024*1024 -> 15728640 | H13: =(H6-G6)*1024*1024 -> 15728640 | I13: =(I6-H6)*1024*1024 -> 15728640 | J13: =$C59/100*$J$6*730/24*1024*1024 -> 9472573.4 | K13: =$C59/100*$J$6*730/24*1024*1024 -> 9472573.4 | L13: =$C59/100*$J$6*730/24*1024*1024 -> 9472573.4 | M13: =$C59/100*$J$6*730/24*1024*1024 -> 9472573.4 | N13: =$C59/100*$J$6*730/24*1024*1024 -> 9472573.4 | O13: =$C59/100*$J$6*730/24*1024*1024 -> 9472573.4 | P13: =$C59/100*$J$6*730/24*1024*1024 -> 9472573.4 | Q13: =$C59/100*$J$6*730/24*1024*1024 -> 9472573.4 | ... AG13: =$C59/100*$J$6*730/24*1024*1024 -> 9472573.4
B14: DTO (GB) | C14: 0.017790254 | D14: =D13/$C$60 -> 1572864 | E14: =E13/$C$60 -> 1572864 | F14: =F13/$C$60 -> 1572864 | G14: =G13/$C$60 -> 1572864 | H14: =H13/$C$60 -> 1572864 | I14: =I13/$C$60 -> 1572864 | J14: =J13/$C$60 -> 947257.34 | K14: =K13/$C$60 -> 947257.34 | ... AG14: =AG13/$C$60 -> 947257.34
B15: PUT per GB Ratio | D15: =D11/D$6/1024/1024 -> 409.6 | E15: =E11/E$6/1024/1024 -> 204.8 | F15: =F11/F$6/1024/1024 -> 136.53333 | G15: =G11/G$6/1024/1024 -> 102.4 | H15: =H11/H$6/1024/1024 -> 81.92 | I15: =I11/I$6/1024/1024 -> 68.266667 | J15: =J11/J$6/1024/1024 -> 47.086287
B16: Get per GB Ratio | D16: =D12/D$6/1024/1024 -> 40.96 | E16: =E12/E$6/1024/1024 -> 20.48 | F16: =F12/F$6/1024/1024 -> 13.653333 | G16: =G12/G$6/1024/1024 -> 10.24 | H16: =H12/H$6/1024/1024 -> 8.192 | I16: =I12/I$6/1024/1024 -> 6.8266667 | J16: =J12/J$6/1024/1024 -> 56.503544
B17: DTO Per GB Ratio | D17: =D14/D6/1024/1024 -> 0.1 | E17: =E14/E6/1024/1024 -> 0.05 | F17: =F14/F6/1024/1024 -> 0.033333333 | G17: =G14/G6/1024/1024 -> 0.025 | H17: =H14/H6/1024/1024 -> 0.02 | I17: =I14/I6/1024/1024 -> 0.016666667 | J17: =J14/J6/1024/1024 -> 0.0100375
B18: Billing STD Total | D18: =D6*C6*1024*1024+D11*C11/1000+D12*C12/10000+D14*C14 -> 99474.707 | E18: =E6*C6*1024*1024+E11*C11/1000+E12*C12/10000+E14*C14 -> 170410.87 | F18: =F6*C6*1024*1024+F11*C11/1000+F12*C12/10000++F14*C14 -> 241347.04 | G18: =G6*C6*1024*1024+G11*C11/1000+G12*C12/10000+G14*C14 -> 312283.21 | H18: =H6*C6*1024*1024+H11*C11/1000+H12*C12/10000++H14*C14 -> 383219.37 | I18: =I6*C6*1024*1024+I11*C11/1000+I12*C12/10000+I14*C14 -> 454155.54 | J18: =J6*C6*1024*1024+J11*C11/1000+J12*C12/10000+J14*C14 -> 443101.6 | K18: =K6*C6*1024*1024+K11*C11/1000+K12*C12/10000+K14*C14 -> 443101.6
B19: Waive 3 SKU | D19: =D11*C11/1000+D12*C12/10000+D14*C14 -> 28538.54 | E19: =E11*C11/1000+E12*C12/10000+E14*C14 -> 28538.54 | F19: =F11*C11/1000+F12*C12/10000+F14*C14 -> 28538.54 | G19: =G11*C11/1000+G12*C12/10000+G14*C14 -> 28538.54 | H19: =H11*C11/1000+H12*C12/10000+H14*C14 -> 28538.54 | I19: =I11*C11/1000+I12*C12/10000+I14*C14 -> 28538.54 | J19: =J11*C11/1000+J12*C12/10000+J14*C14 -> 17484.6 | K19: =K11*C11/1000+K12*C12/10000+K14*C14 -> 17484.6
B21: S-IA
B22: PUT | C22: 0.00089 | D22: =D25/$C$54*1024 -> 15032385536 | E22: =E25/$C$54*1024 -> 15032385536 | F22: =F25/$C$54*1024 -> 15032385536 | G22: =G25/$C$54*1024 -> 15032385536 | H22: =H25/$C$54*1024 -> 15032385536 | I22: =I25/$C$54*1024 -> 15032385536 | J22: =J11/$J$6*$J$7*$C$61 -> 3110533650 | K22: =K11/$J$6*$J$7*$C$61 -> 3110533650 | L22: =L11/$J$6*$J$7*$C$61 -> 3110533650 | M22: =M11/$J$6*$J$7*$C$61 -> 3110533650 | N22: =N11/$J$6*$J$7*$C$61 -> 3110533650 | O22: =O11/$J$6*$J$7*$C$61 -> 3110533650 | P22: =P11/$J$6*$J$7*$C$61 -> 3110533650 | Q22: =Q11/$J$6*$J$7*$C$61 -> 3110533650 | ... AG22: =AG11/$J$6*$J$7*$C$61 -> 3110533650
B23: GET | C23: 0.003 | D23: =D26/$C$54*1024 -> 4.5097157e+08 | E23: =E26/$C$54*1024 -> 4.5097157e+08 | F23: =F26/$C$54*1024 -> 4.5097157e+08 | G23: =G26/$C$54*1024 -> 4.5097157e+08 | H23: =H26/$C$54*1024 -> 4.5097157e+08 | I23: =I26/$C$54*1024 -> 4.5097157e+08 | J23: =J12/$J$6*$J$7*$C$61 -> 3732640380 | K23: =K12/$J$6*$J$7*$C$61 -> 3732640380 | L23: =L12/$J$6*$J$7*$C$61 -> 3732640380 | M23: =M12/$J$6*$J$7*$C$61 -> 3732640380 | N23: =N12/$J$6*$J$7*$C$61 -> 3732640380 | O23: =O12/$J$6*$J$7*$C$61 -> 3732640380 | P23: =P12/$J$6*$J$7*$C$61 -> 3732640380 | Q23: =Q12/$J$6*$J$7*$C$61 -> 3732640380 | ... AG23: =AG12/$J$6*$J$7*$C$61 -> 3732640380
B24: Data Retrieval (GB) | C24: 0.0021 | D24: =D26 -> 1101004.8 | E24: =E26 -> 1101004.8 | F24: =F26 -> 1101004.8 | G24: =G26 -> 1101004.8 | H24: =H26 -> 1101004.8 | I24: =I26 -> 1101004.8 | J24: =J23*$C54/1024 -> 9112891.6 | K24: =K23*$C54/1024 -> 9112891.6 | L24: =L23*$C54/1024 -> 9112891.6 | M24: =M23*$C54/1024 -> 9112891.6 | N24: =N23*$C54/1024 -> 9112891.6 | O24: =O23*$C54/1024 -> 9112891.6 | P24: =P23*$C54/1024 -> 9112891.6 | Q24: =Q23*$C54/1024 -> 9112891.6 | ... AG24: =AG23*$C54/1024 -> 9112891.6
B25: DTI (GB) | D25: =D7*1024*1024 -> 36700160 | E25: =(E7-D7)*1024*1024 -> 36700160 | F25: =(F7-E7)*1024*1024 -> 36700160 | G25: =(G7-F7)*1024*1024 -> 36700160 | H25: =(H7-G7)*1024*1024 -> 36700160 | I25: =(I7-H7)*1024*1024 -> 36700160 | J25: =J13/$J$6*$J$7*$C$61 -> 6630801.4 | K25: =K13/$J$6*$J$7*$C$61 -> 6630801.4 | L25: =L13/$J$6*$J$7*$C$61 -> 6630801.4 | M25: =M13/$J$6*$J$7*$C$61 -> 6630801.4 | N25: =N13/$J$6*$J$7*$C$61 -> 6630801.4 | O25: =O13/$J$6*$J$7*$C$61 -> 6630801.4 | P25: =P13/$J$6*$J$7*$C$61 -> 6630801.4 | Q25: =Q13/$J$6*$J$7*$C$61 -> 6630801.4 | ... AG25: =AG13/$J$6*$J$7*$C$61 -> 6630801.4
B26: DTO (GB) | C26: 0.017790254 | D26: =D25/$C$60*$C$61 -> 1101004.8 | E26: =E25/$C$60*$C$61 -> 1101004.8 | F26: =F25/$C$60*$C$61 -> 1101004.8 | G26: =G25/$C$60*$C$61 -> 1101004.8 | H26: =H25/$C$60*$C$61 -> 1101004.8 | I26: =I25/$C$60*$C$61 -> 1101004.8 | J26: =J14/$J$6*$J$7*$C$61 -> 663080.14 | K26: =K14/$J$6*$J$7*$C$61 -> 663080.14 | L26: =L14/$J$6*$J$7*$C$61 -> 663080.14 | M26: =M14/$J$6*$J$7*$C$61 -> 663080.14 | N26: =N14/$J$6*$J$7*$C$61 -> 663080.14 | O26: =O14/$J$6*$J$7*$C$61 -> 663080.14 | P26: =P14/$J$6*$J$7*$C$61 -> 663080.14 | Q26: =Q14/$J$6*$J$7*$C$61 -> 663080.14 | ... AG26: =AG14/$J$6*$J$7*$C$61 -> 663080.14
B27: PUT per GB Ratio | D27: =D22/D$7/1024/1024 -> 409.6 | E27: =E22/E$7/1024/1024 -> 204.8 | F27: =F22/F$7/1024/1024 -> 136.53333 | G27: =G22/G$7/1024/1024 -> 102.4 | H27: =H22/H$7/1024/1024 -> 81.92 | I27: =I22/I$7/1024/1024 -> 68.266667 | J27: =J22/J$7/1024/1024 -> 14.125886
B28: Get per GB Ratio | D28: =D23/D$7/1024/1024 -> 12.288 | E28: =E23/E$7/1024/1024 -> 6.144 | F28: =F23/F$7/1024/1024 -> 4.096 | G28: =G23/G$7/1024/1024 -> 3.072 | H28: =H23/H$7/1024/1024 -> 2.4576 | I28: =I23/I$7/1024/1024 -> 2.048 | J28: =J23/J$7/1024/1024 -> 16.951063
B29: DTO Per GB Ratio | D29: =D26/D7/1024/1024 -> 0.03 | E29: =E26/E7/1024/1024 -> 0.015 | F29: =F26/F7/1024/1024 -> 0.01 | G29: =G26/G7/1024/1024 -> 0.0075 | H29: =H26/H7/1024/1024 -> 0.006 | I29: =I26/I7/1024/1024 -> 0.005 | J29: =J26/J7/1024/1024 -> 0.00301125
B30: Billing S-IA Total | D30: =D7*C7*1024*1024+D22*C22/1000+D23*C23/10000+D24*C24+D26*C26 -> 105510.69 | E30: =E7*C7*1024*1024+E22*C22/1000+E23*C23/10000+E24*C24+E26*C26 -> 175607.99 | F30: =F7*C7*1024*1024+F22*C22/1000+F23*C23/10000+F24*C24+F26*C26 -> 245705.3 | G30: =G7*C7*1024*1024+G22*C22/1000+G23*C23/10000+G24*C24+G26*C26 -> 315802.6 | H30: =H7*C7*1024*1024+H22*C22/1000+H23*C23/10000+H24*C24+H26*C26 -> 385899.91 | I30: =I7*C7*1024*1024+I22*C22/1000+I23*C23/10000+I24*C24+I26*C26 -> 455997.21 | J30: =J7*C7*1024*1024+J22*C22/1000+J23*C23/10000+J24*C24+J26*C26 -> 455405.44 | K30: =K7*C7*1024*1024+K22*C22/1000+K23*C23/10000+K24*C24+K26*C26 -> 455405.44
B31: Waive 3 SKU | D31: =D26*C26 -> 19587.155 | E31: =E26*C26 -> 19587.155 | F31: =F26*C26 -> 19587.155 | G31: =G26*C26 -> 19587.155 | H31: =H26*C26 -> 19587.155 | I31: =I26*C26 -> 19587.155 | J31: =J26*C26 -> 11796.364 | K31: =K26*C26 -> 11796.364
B33: Billing Total | D33: =D18+D30 -> 204985.39 | E33: =E18+E30 -> 346018.86 | F33: =F18+F30 -> 487052.34 | G33: =G18+G30 -> 628085.81 | H33: =H18+H30 -> 769119.28 | I33: =I18+I30 -> 910152.75 | J33: =J18+J30 -> 898507.04 | K33: =K18+K30 -> 898507.04
B34: Waive Total | D34: =D19+D31 -> 48125.696 | E34: =E19+E31 -> 48125.696 | F34: =F19+F31 -> 48125.696 | G34: =G19+G31 -> 48125.696 | H34: =H19+H31 -> 48125.696 | I34: =I19+I31 -> 48125.696 | J34: =J19+J31 -> 29280.964 | K34: =K19+K31 -> 29280.964
B35: After waived charging Total | D35: =D33-D34 -> 156859.7 | E35: =E33-E34 -> 297893.17 | F35: =F33-F34 -> 438926.64 | G35: =G33-G34 -> 579960.11 | H35: =H33-H34 -> 720993.58 | I35: =I33-I34 -> 862027.06 | J35: =J33-J34 -> 869226.07 | K35: =K33-K34 -> 869226.07
B36: Average to per GB before Waive USD | D36: =D33/D8/1024/1024 -> 0.0039097861 | E36: =E33/E8/1024/1024 -> 0.003299893 | F36: =F33/F8/1024/1024 -> 0.0030965954 | G36: =G33/G8/1024/1024 -> 0.0029949465 | H36: =H33/H8/1024/1024 -> 0.0029339572 | I36: =I33/I8/1024/1024 -> 0.0028932977 | J36: =J33/J8/1024/1024 -> 0.0028562769 | K36: =K33/K8/1024/1024 -> 0.0028562769
B37: Average to per GB before Waive RMB (人民币分/GB) | D37: =D36*7.08*100 -> 2.7681285 | E37: =E36*7.08*100 -> 2.3363243 | F37: =F36*7.08*100 -> 2.1923895 | G37: =G36*7.08*100 -> 2.1204221 | H37: =H36*7.08*100 -> 2.0772417 | I37: =I36*7.08*100 -> 2.0484548 | J37: =J36*7.08*100 -> 2.0222441 | K37: =K36*7.08*100 -> 2.0222441
B38: Average to per GB after Waive USD | D38: =D35/D8/1024/1024 -> 0.0029918613 | E38: =E35/E8/1024/1024 -> 0.0028409306 | F38: =F35/F8/1024/1024 -> 0.0027906204 | G38: =G35/G8/1024/1024 -> 0.0027654653 | H38: =H35/H8/1024/1024 -> 0.0027503723 | I38: =I35/I8/1024/1024 -> 0.0027403102 | J38: =J35/J8/1024/1024 -> 0.0027631953 | K38: =K35/K8/1024/1024 -> 0.0027631953
B39: Average to per GB after Waive RMB (人民币分/GB) | D39: =D38*7.08*100 -> 2.1182378 | E39: =E38*7.08*100 -> 2.0113789 | F39: =F38*7.08*100 -> 1.9757593 | G39: =G38*7.08*100 -> 1.9579494 | H39: =H38*7.08*100 -> 1.9472636 | I39: =I38*7.08*100 -> 1.9401396 | J39: =J38*7.08*100 -> 1.9563422 | K39: =K38*7.08*100 -> 1.9563422
H41: Y2025 Rev | I41: =SUM(D33:I33) -> 3345414.4
H42: Y2025 Credit | I42: =SUM(D34:I34) -> 288754.17
H43: Stable MRR | I43: =J33 -> 898507.04
H44: Stable Credit per Month | I44: =J34 -> 29280.964
H45: Stable ARR | I45: =I43*12 -> 10782084
H46: Stable Credit per yr | I46: =I44*12 -> 351371.57
...

Sheet Pricing Optimization Proposal
A2: Y2025 Rev | B2: 3345414.4
A3: Y2025 Credit | B3: 288754.17
A4: Stable MRR | B4: 898507.04
A5: Stable Credit per Month | B5: 29280.964
A6: Stable ARR | B6: 10782084
A7: Stable Credit per yr | B7: 351371.57
A9: 3 yrs
A10: Revenue | B10: =B2+B6*2.5 -> 30300625
A11: Waive 3 SKU Credit | B11: =B3+B7*2.5 -> 1167183.1
A12: Revenue after waive | B12: =B10-B11 -> 29133442
A13: Total charge capacity | B13: =SUM('Data Ramp Plan'!D8:I8)+300*12*2.5 -> 10050
A14: All-in-one Pricing | B14: USD per month per GB | C14: 人民币分每GB每月
A15: Approved | B15: =B10/B13/1024/1024 -> 0.0028753162 | C15: =B15*B23*100 -> 2.0357239
A16: Waive 3 SKU | B16: =B12/B13/1024/1024 -> 0.0027645588 | C16: =B16*B23*100 -> 1.9573076
A17: Requested 1.5 with TAX | B17: =C17/B23/100 -> 0.0019987208 | C17: =1.5/1.06 -> 1.4150943
A19: Revenue on Requested Price | B19: =B17*B13*1024*1024 -> 21062897
A20: After Waive Extra Credit | B20: =B12-B19 -> 8070545.1
A21: Total Credit | B21: =B20+B11 -> 9237728.2
A23: CNY:USD rate | B23: 7.08

Sheet Assumption
B2: Assumption | C2: Hot:Cold mix is 3:7
C3: Hot | D3: S3 Standard | E3: 0.3
C4: Cold | D4: S3 IA | E4: 0.7
B5: Storage size | C5: 300 | D5: PB
B6: Average object size | C6: 2.5 | D6: MB | E6: ='Data Ramp Plan'!E54 -> Actual AOS based on existing vendors' use case
B7: Put peak QPS | C7: 11.25 | D7: K/s | E7: ='Data Ramp Plan'!E55 -> per China Mobile RFI file and Baidu Cloud recent operation data
B8: Get peak QPS | C8: 13.5 | D8: K/s | E8: The estimated bandwidth size is 13500 (Put Peak QPS) * 2.5 (average file size) / 1024 (converted to GB/s) * 8 (converted to bandwidth unit Gbps) = 264Gbps
B9: Delete peak QPS | C9: 18.5 | D9: K/s | E9: per China Mobile RFI file and Baidu Cloud recent operation data
B10: Peak to Average ratio | C10: 0.167 | E10: per iCloud working mechanism, the data ingestion will happen on the condition with Wifi connection and in charging, we assume the ingestion will only happen during 1-5 am (4 hours/24 hours = 16.7%)
B11: Daily DTI | C11: 0.33 | D11: PB | E11: Based on China Mobile and Baidu Cloud iCloud workload operation data
B13: Public price (CNY) | C13: Exchange Rate | D13: 7.08 | E13: AWS STD exchange rate for H2'2024
B14: Region | C14: S3 Tiering | D14: Storage Price | E14: PUT price (per 1,000) | F14: GET price (per 10,000) | G14: Data Retrieval (per GB) | H14: DTO (per GB)
B15: BJS | C15: S3-STD | D15: 0.181 | E15: 0.0045 | F15: 0.015 | G15: 0 | H15: 0.933
C16: S3-IA | D16: 0.13377 | E16: 0.0637 | F16: 0.0637 | G16: 0.0637 | H16: 0.933
B17: ZHY | C17: S3-STD | D17: 0.1629 | E17: 0.00405 | F17: 0.0135 | G17: 0 | H17: 0.933
C18: S3-IA | D18: 0.103 | E18: 0.04905 | F18: 0.04905 | G18: 0.0637 | H18: 0.933
B20: Public price (USD)
B21: Region | C21: S3 Tiering | D21: Storage Price | E21: PUT price (per 1,000) | F21: GET price (per 10,000) | G21: Data Retrieval (per GB) | H21: DTO (per GB)
B22: BJS | C22: S3-STD | D22: =D15/$D$13 -> 0.025564972 | E22: =E15/$D$13 -> 0.00063559322 | F22: =F15/$D$13 -> 0.0021186441 | H22: =H15/$D$13 -> 0.13177966
C23: S3-IA | D23: =D16/$D$13 -> 0.018894068 | E23: =E16/$D$13 -> 0.0089971751 | F23: =F16/$D$13 -> 0.0089971751 | G23: =G16/$D$13 -> 0.0089971751 | H23: =H16/$D$13 -> 0.13177966
B24: ZHY | C24: S3-STD | D24: =D17/$D$13 -> 0.023008475 | E24: =E17/$D$13 -> 0.0005720339 | F24: =F17/$D$13 -> 0.0019067797 | H24: =H17/$D$13 -> 0.13177966
C25: S3-IA | D25: =D18/$D$13 -> 0.014548023 | E25: =E18/$D$13 -> 0.0069279661 | F25: =F18/$D$13 -> 0.0069279661 | G25: =G18/$D$13 -> 0.0089971751 | H25: =H18/$D$13 -> 0.13177966
C27: BJS disc -> | D27: 0.911 | E27: 0.925 | F27: 0.76 | G27: 0.836 | H27: 0.865 | I27: <= update yellow cells to adjust disc ask
B28: Private price (USD) | C28: ZHY disc -> | D28: 0.896 | E28: =E27 -> 0.925 | F28: =F27 -> 0.76 | G28: =G27 -> 0.836 | H28: =H27 -> 0.865
B29: Region | C29: S3 Tiering | D29: Storage Price | E29: PUT price (per 1,000) | F29: GET price (per 10,000) | G29: Data Retrieval (per GB) | H29: DTO (per GB) | L29: check global DTO disc
B30: BJS | C30: S3-STD | D30: =(1-D$27)*D22 -> 0.0022752825 | E30: =(1-E$27)*E22 -> 4.7669492e-05 | F30: =(1-F$27)*F22 -> 0.00050847458 | H30: =(1-H$27)*H22 -> 0.017790254
C31: S3-IA | D31: =(1-D$27)*D23 -> 0.001681572 | E31: =(1-E$27)*E23 -> 0.00067478814 | F31: =(1-F$27)*F23 -> 0.002159322 | G31: =(1-G$27)*G23 -> 0.0014755367 | H31: =(1-H$27)*H23 -> 0.017790254 | L31: 6家 vendor situation
B32: ZHY | C32: S3-STD | D32: =(1-D$28)*D24 -> 0.0023928814 | E32: =(1-E$28)*E24 -> 4.2902542e-05 | F32: =(1-F$28)*F24 -> 0.00045762712 | H32: =(1-H$28)*H24 -> 0.017790254 | L32: 那张图
C33: S3-IA | D33: =(1-D$28)*D25 -> 0.0015129944 | E33: =(1-E$28)*E25 -> 0.00051959746 | F33: =(1-F$28)*F25 -> 0.0016627119 | G33: =(1-G$28)*G25 -> 0.0014755367 | H33: =(1-H$28)*H25 -> 0.017790254 | L33: 上次啥价格
L34: 上次为啥要走 partner
B35: Customer Data access pattern
B36: Region | C36: S3 Tiering | D36: Usage (PB) | E36: PUT Monthly Volume (per 1,000) | F36: Get Monthly (per 10,000) | G36: Data Retrieval (GB) | H36: DTO (GB)
B37: BJS | C37: S3-STD | D37: 90 | E37: ='Data Ramp Plan'!J11/1000 -> 4443619.5 | F37: ='Data Ramp Plan'!J12/10000 -> 533234.34 | G37: 0 | H37: ='Data Ramp Plan'!J14 -> 947257.34
C38: S3-IA | D38: 210 | E38: ='Data Ramp Plan'!J22/1000 -> 3110533.6 | F38: ='Data Ramp Plan'!J23/10000 -> 373264.04 | G38: ='Data Ramp Plan'!J24 -> 9112891.6 | H38: ='Data Ramp Plan'!J26 -> 663080.14
B39: ZHY | C39: S3-STD | D39: 90 | E39: =E37 -> 4443619.5 | F39: =F37 -> 533234.34 | G39: =G37 -> 0 | H39: =H37 -> 947257.34
C40: S3-IA | D40: 210 | E40: =E38 -> 3110533.6 | F40: =F38 -> 373264.04 | G40: =G38 -> 9112891.6 | H40: =H38 -> 663080.14
B42: Inclusive (Storage, API calls and DTO) Total Cost after discount - In USD
B43: Region | C43: S3 Tiering | D43: Storage | E43: PUT | F43: GET | G43: Data Retrieval | H43: DTO
B44: BJS | C44: S3-STD | D44: =D37*1024*1024*D30 -> 214722.59 | E44: =E37*E30 -> 211.82508 | F44: =F37*F30 -> 271.13611 | G44: =G37*G30 -> 0 | H44: =H37*H30 -> 16851.949
C45: S3-IA | D45: =D38*1024*1024*D31 -> 370283.78 | E45: =E38*E31 -> 2098.9512 | F45: =F38*F31 -> 805.99726 | G45: =G38*G31 -> 13446.406 | H45: =H38*H31 -> 11796.364
...

Sheet Deal Model Inputs (2)
A1: S3/Glacier Approval Intake Template
A3: Question | B3: OVERVIEW
A4: M | B4: Please provide a high level summary of the deal (For ex. What is the ask, what makes it custom, is it a renewal or an existing customer and are we facing a compete situation?)
B5: Input answer here
A6: M | B6: Customer Name | M6: Input here
A7: M | B7: Payer ID (all, if there are multiple) | M7: Input here
A8: M | B8: Deal Effective Date | M8: MM/DD/YYYY
A9: M | B9: Term (months) | M9: Input here
A10: M | B10: Is this a no-commit deal? | M10: select
A11: M | B11: Does this deal require price protection? | M11: select
A12: M | B12: Link to prior approval if any | M12: Input here
A13: M | B13: Does this deal require above PARC discounts? (deals which would not fall in this are PARC deals with SFO addition, non - custom PARC term etc) | M13: select
A14: M | B14: If your answer to above question is NO, please explain what makes this deal custom | M14: Input here
B15: REGIONS AND STORAGE
A16: M | B16: Total starting storage across all classes | M16: Input here in PB
A17: M | B17: Total ending storage across all classes | M17: Input here in PB
B18: Class | D18: STD/INT FA | F18: SIA/INT IA | H18: ZIA | J18: INT | L18: Glacier/INT AA | N18: Glacier Deep Archive/INT DAA
A19: M | B19: Discount | D19: Input discount here in % | F19: Input discount here in % | H19: Input discount here in % | J19: Input discount here in % | L19: Input discount here in % | N19: Input discount here in % | P19: Instructions
B20: Regions: | C20: Is the discount within PARC for this region? | D20: insert % of total storage in STD | F20: insert % of total storage in SIA | H20: insert % of total storage in ZIA | J20: insert % of total storage in INT | L20: insert % of total storage in Glacier | N20: insert % of total storage GDA | P20: 1. Please input the storage in each region for a given class as a % of total storage. Cells D20-O20 must add upto 100% 2. Please input regional % storage split of each class in cells DE22-NO33. Entries for each column per storage class must add to 100% 3. If there is no current/future storage in a region, please write N/A 4. If INT is involved, input the split between FA/IA/AA/DAA in cell S19-23 | S20: Input INT split (must add to 100%) | U20: INT is a storage classs which intelligently routes data to STD/SIA/Glacier/GDA based on how frequently it is accessed. INT FA goes to STD, IA goes to SIA, AA goes to glacier and DAA goes to GDA. The default % are 10, 20, 30 and 40 respectively.
A21: M | B21: select | C21: select | D21: Insert % of total STD storage in this region | F21: Insert % of total SIA storage in this region | H21: Insert % of total ZIA storage in this region | J21: Insert % of total INT storage in this region | L21: Insert % of total Glacier storage in this region | N21: Insert % of total GDA storage in this region | S21: FA | T21: 0.1
B22: select | C22: select | D22: Insert % of total STD storage in this region | F22: Insert % of total SIA storage in this region | H22: Insert % of total ZIA storage in this region | J22: Insert % of total INT storage in this region | L22: Insert % of total Glacier storage in this region | N22: Insert % of total GDA storage in this region | S22: IA | T22: 0.2
B23: select | C23: select | D23: Insert % of total STD storage in this region | F23: Insert % of total SIA storage in this region | H23: Insert % of total ZIA storage in this region | J23: Insert % of total INT storage in this region | L23: Insert % of total Glacier storage in this region | N23: Insert % of total GDA storage in this region | S23: AA | T23: 0.3
B24: select | C24: select | D24: Insert % of total STD storage in this region | F24: Insert % of total SIA storage in this region | H24: Insert % of total ZIA storage in this region | J24: Insert % of total INT storage in this region | L24: Insert % of total Glacier storage in this region | N24: Insert % of total GDA storage in this region | S24: DAA | T24: 0.4
B25: select | C25: select | D25: Insert % of total STD storage in this region | F25: Insert % of total SIA storage in this region | H25: Insert % of total ZIA storage in this region | J25: Insert % of total INT storage in this region | L25: Insert % of total Glacier storage in this region | N25: Insert % of total GDA storage in this region
B26: select | C26: select | D26: Insert % of total STD storage in this region | F26: Insert % of total SIA storage in this region | H26: Insert % of total ZIA storage in this region | J26: Insert % of total INT storage in this region | L26: Insert % of total Glacier storage in this region | N26: Insert % of total GDA storage in this region
B27: select | C27: select | D27: Insert % of total STD storage in this region | F27: Insert % of total SIA storage in this region | H27: Insert % of total ZIA storage in this region | J27: Insert % of total INT storage in this region | L27: Insert % of total Glacier storage in this region | N27: Insert % of total GDA storage in this region
B28: select | C28: select | D28: Insert % of total STD storage in this region | F28: Insert % of total SIA storage in this region | H28: Insert % of total ZIA storage in this region | J28: Insert % of total INT storage in this region | L28: Insert % of total Glacier storage in this region | N28: Insert % of total GDA storage in this region
B29: select | C29: select | D29: Insert % of total STD storage in this region | F29: Insert % of total SIA storage in this region | H29: Insert % of total ZIA storage in this region | J29: Insert % of total INT storage in this region | L29: Insert % of total Glacier storage in this region | N29: Insert % of total GDA storage in this region
B30: select | C30: select | D30: Insert % of total STD storage in this region | F30: Insert % of total SIA storage in this region | H30: Insert % of total ZIA storage in this region | J30: Insert % of total INT storage in this region | L30: Insert % of total Glacier storage in this region | N30: Insert % of total GDA storage in this region
B31: select | C31: select | D31: Insert % of total STD storage in this region | F31: Insert % of total SIA storage in this region | H31: Insert % of total ZIA storage in this region | J31: Insert % of total INT storage in this region | L31: Insert % of total Glacier storage in this region | N31: Insert % of total GDA storage in this region
B32: select | C32: select | D32: Insert % of total STD storage in this region | F32: Insert % of total SIA storage in this region | H32: Insert % of total ZIA storage in this region | J32: Insert % of total INT storage in this region | L32: Insert % of total Glacier storage in this region | N32: Insert % of total GDA storage in this region
B33: Is the % starting and ending storage the same in a given region and class? For ex. In IAD, will the STD storage be 10% for both starting/ending storage or will the ending storage will more/less than starting storage as a %. If it will be different, please fill the detailed sheet in attachments tab.
B34: USAGE/STORAGE PATTERN (These inputs impact margins significantly) | P34: Instructions
A35: M | B35: Delete / GB stored on a monthly basis | M35: Input here in % | P35: Avg object size and delete rate are critical inputs to a deal model. If actuals are not available, please input a range. For example of object size, images are in the range of MBs, and video files are in the range of GBs. For delete rates, you can input low (0-10%), medium (10-25%) or high (>25%)
A36: M | B36: Is there a discount requested for PUT/GET? | M36: select
A37: M | B37: If yes, input discount | M37: Input here
A38: M | B38: Avg Object Size | M38: Input here
A39: M | B39: Are there any objects <70KB? | M39: Input here
A40: M | B40: Is there a discount requested for retrievals? | M40: select
A41: M | B41: If yes, input discount | M41: Input here
...

Sheet Discount Ask
B1: S3/Glacier Private Deal Approval Intake Form In absence of clear inputs for mandatory* fields marked, the request will not be qualified
B2: Amazon S3 Standard Storage and Amazon S3 Intelligent-Tiering Storage, Frequent Access | E2: Enter N/A if this class is not discounted
B3: If discounted, please select the discounted class/tier? | E3: select
B4: Region | C4: Requested Price (SCE/GSP/WWPS only)* | D4: Requested discount against public pricing* | E4: Explaination*
B5: select region | C5: Enter in $/GB | D5: Enter in % | E5: [1] Explain why discounts are above PARC? <insert answer here> [2] Explain why discounts are different/same for all storage classes? <insert answer here> [3] Explain why discounts are different/same for all regions? <insert answer here>
B6: select region | C6: Enter in $/GB | D6: Enter in %
B7: select region | C7: Enter in $/GB | D7: Enter in %
B8: select region | C8: Enter in $/GB | D8: Enter in %
B9: select region | C9: Enter in $/GB | D9: Enter in %
B10: select region | C10: Enter in $/GB | D10: Enter in %
B11: select region | C11: Enter in $/GB | D11: Enter in %
B12: select region | C12: Enter in $/GB | D12: Enter in %
B13: select region | C13: Enter in $/GB | D13: Enter in %
B14: select region | C14: Enter in $/GB | D14: Enter in %
B15: select region | C15: Enter in $/GB | D15: Enter in %
B16: select region | C16: Enter in $/GB | D16: Enter in %
B17: Amazon S3 Standard-Infrequent Access Storage & Amazon S3 Intelligent-Tiering Storage, Infrequent Access | E17: Enter N/A if this class is not discounted
B18: If discounted, please select the discounted class/tier? | E18: select
B19: Region | C19: Requested Price* | D19: Requested against public pricing* | E19: Explaination*
B20: select region | C20: Enter in $/GB | D20: Enter in % | E20: [1] Explain why discounts are above PARC? <insert answer here> [2] Explain why discounts are different/same for all storage classes? <insert answer here> [3] Explain why discounts are different/same for all regions? <insert answer here>
B21: select region | C21: Enter in $/GB | D21: Enter in %
B22: select region | C22: Enter in $/GB | D22: Enter in %
B23: select region | C23: Enter in $/GB | D23: Enter in %
B24: select region | C24: Enter in $/GB | D24: Enter in %
B25: select region | C25: Enter in $/GB | D25: Enter in %
B26: select region | C26: Enter in $/GB | D26: Enter in %
B27: select region | C27: Enter in $/GB | D27: Enter in %
B28: select region | C28: Enter in $/GB | D28: Enter in %
B29: select region | C29: Enter in $/GB | D29: Enter in %
B30: select region | C30: Enter in $/GB | D30: Enter in %
B31: select region | C31: Enter in $/GB | D31: Enter in %
B32: select region | C32: Enter in $/GB | D32: Enter in %
B33: Amazon S3 One Zone - Infrequent Access Storage | E33: Enter N/A if this class is not discounted
B34: Region | C34: Requested Price* | D34: Requested against public pricing* | E34: Explaination*
B35: select region | C35: Enter in $/GB | D35: Enter in % | E35: [1] Explain why discounts are above PARC? <insert answer here> [2] Explain why discounts are different/same for all storage classes? <insert answer here> [3] Explain why discounts are different/same for all regions? <insert answer here>
B36: select region | C36: Enter in $/GB | D36: Enter in %
B37: select region | C37: Enter in $/GB | D37: Enter in %
B38: select region | C38: Enter in $/GB | D38: Enter in %
B39: select region | C39: Enter in $/GB | D39: Enter in %
B40: select region | C40: Enter in $/GB | D40: Enter in %
...

Sheet Deal Inputs
A1: Question | L1: Response
A2: Give a brief description of the workloads, data flow and architecture. What does the customer use S3/Glacier for, how does the data flow in AWS to S3, how is it accessed and how are the selected storage classes suitable for the customer (explain for all requested workloads/storage classes. For ex, data is initially hot and stored in standard for further processing from where it is then aggregated and moved into a colder tier)? TAM/SA should ideally answer this question. | L2: Fruitstand China iCloud workload.
A3: Is this deal for an existing workload? If yes, how have we ensured the customer is currently optimized in terms of storage class usage (for example, using GIR for colder data that needs instant access)? Is the customer planning any usage or region mix shift? Please explain. | L3: This a net new deal, Fruitstand China iCloud storage workload.
A4: Is this deal for a new workload? If yes, where are these workloads currently housed and what is the current usage workflow (for example, explain the on-prem use case if the deal is an on prem compete)? | L4: Currently, Fruitstand China utilizes six third-party object storage service providers to share the iCloud storage capacity in China. Additionally, Fruitstand China has built two data centers in the country, and the on-premise solution also contributes to the storage capacity share.
A5: What role will Cloud storage play in the customer's infrastructure (e.g., will they use the Cloud as a secondary copy only (and maintain their primary copy on-prem, hybrid, or will they use the Cloud as their only copy (no longer use on-prem)? | L5: AWS S3 would be used as the primary copy.
A6: If a renewal, is this deal bringing any incremental workloads, or is it only organic growth? Please explain. | L6: This is not renewal.
A7: If applicable, please explain the expected adoption of GIR and Intelligent tiering. Why is it critical to the deal and why is private pricing necessary for it? | L7: Based on the Fruitstand iCloud S3 user case in global regions, we propose S3-STD and S3-IA for iCloud China.
A8: Does the deal require above PARC discounts? If not, what makes it custom and why is a requirement for the customer? (non-linear ramp, annual check-ins, etc) | L8: Yes.
A9: Starting commitment (for net new workloads, input 0 PB) | L9: 0
A10: Ending commitment | L10: 300PB
A11: Is the starting commit lower than their current usage. If yes, why? Additionally, is the customer planning any deletes? Please explain. | L11: This is a new workload.
A12: Does the ending commit account for all of the customers projected growth? If not, please explain why is the customer hesitant to higher commitment. | L12: Fruitstand will evaluate to choose vendors for iCloud before end of contract, if we can not win the contract at that time, customer will move data to new vendor.
A13: Is the ramp linear? If no, please provide ramp schedule in the response with the region and class mix included | L13: If we won the deal, the total peak storage usage is 300PB, the ingest plan from Fruitstand China is to linearly grow data to meet 300PB during 6 months, then keep 300PB on AWS for 30 months when keep to ingest and delete data during the time. During the 36 months, customer will daily ingest 0.5PB to AWS via public internet. The average object size is 2.5MB.
A14: If this is an existing customer with new incoming workloads, what are the usage patterns of the new workload (retrievals, DTO, etc)? Are they similar to their current usage patterns? If yes, how? If no, please complete the additional details section. | L14: This is a new workload.
A16: Please complete the storage class and region mix breakdown below. For existing customers, please indicate the change in future storage mix. If there is no change, please input "per historical usage."
B17: S3 Standard (STD) | D17: S3 Standard Infrequent Access (SIA) | F17: S3 One Zone Infrequent Access (ZIA) | H17: S3 Glacier Instant Retrieval (GIR) | J17: S3 Glacier Flexible Retrieval (GFR) | L17: S3 Glacier Deep Archive (GDA) | N17: S3 Intelligent Tiering (INT) | P17: Total | R17: If INT is included, please indicate split (in %)
A18: Starting Mix | B18: 0.3 | D18: 0.7 | F18: 0 | H18: 0 | P18: 1 | R18: FA | S18: IA | T18: AIA | U18: AA | V18: DAA
A19: Ending Mix | B19: 0.3 | D19: 0.7 | P19: 1
R20: INT is a storage class which intelligently routes data to INT FA/INT IA/INT AIA/Int AA/INT DAA based on how frequently it is accessed.
C21: Starting Regional Storage Mix | F21: Ending Regional Storage Mix*
A22: BJS | C22: 1 | F22: 1 | I22: <= The workload could be hosted in either the BJS or ZHY, but all data would need to be stored in a single region.
A23: ZHY | C23: 1 | F23: 1 | I23: We would appreciate the service team's recommendation on the preferred AWS region.
A24: select region
A25: select region
A26: select region
A27: select region
A28: select region
A29: select region
A30: select region
A31: select region
A32: select region
A33: select region
A34: Total | C34: 1 | F34: 1
A35: *Only input ending storage mix if the customer expects changes during the term length of the PPA
A37: Please input the discounted rates being requested for each storage class by region.
A38: S3 Standard and S3 Intelligent-Tiering Frequent Access (INT-FA) | E38: Standard Infrequent Access (SIA) & S3 Intelligent-Tiering Infrequent Access (INT-IA) | I38: One Zone Infrequent Access (ZIA) | M38: Glacier Instant Retrieval (GIR) & S3 Intelligent Tiering Archive Instant Access (INT-AIA) | Q38: Glacier Flexible Retrieval (GFR) & S3 Intelligent-Tiering Archive Access (INT-AA) | U38: Glacier Deep Archive (GDA) & S3 Intelligent-Tiering Storage Deep Access Archive (DAA)
A39: Is discount % also requested on INT? Y/N | C39: Input | E39: Is discount % also requested on INT? Y/N | G39: Input | I39: Is discount % also requested on INT? Y/N | K39: Input | M39: Is discount % also requested on INT? Y/N | O39: Input | Q39: Is discount % also requested on INT? Y/N | S39: Input | U39: Is discount % also requested on INT? Y/N | W39: Input
A40: Region | B40: Requested Rate | C40: Requested Discount | E40: Region | F40: Requested Rate | G40: Requested Discount | I40: Region | J40: Requested Rate | K40: Requested Discount | M40: Region | N40: Requested Rate | O40: Requested Discount | Q40: Region | R40: Requested Rate | S40: Requested Discount | U40: Region | V40: Requested Rate | W40: Requested Discount
A41: BJS | B41: =0.016109/7.08 -> 0.0022752825 | C41: 0.911 | E41: BJS | F41: =0.01190553/7.08 -> 0.001681572 | G41: 0.911 | I41: select region | J41: $/GB | K41: % | M41: select region | N41: $/GB | O41: % | Q41: select region | R41: $/GB | S41: % | U41: select region | V41: $/GB | W41: %
A42: ZHY | B42: =0.0169416/7.08 -> 0.0023928814 | C42: =1-10.4% -> 0.896 | E42: ZHY | F42: =0.010712/7.08 -> 0.0015129944 | G42: =1-10.4% -> 0.896 | I42: select region | M42: select region | Q42: select region | U42: select region
...

Sheet Business Justification
A2: Question | B2: Response
A3: Customer Name | B3: Fruitstand China
A4: Please explain the customer's relationship with AWS. What is their % spend on S3 and is that expected to change? | B4: Fruitstand is a key strategic account for AWS and one of the top consumers of S3 services in global regions. However, in Fruitstand China, there is currently 0% spend on S3. We are targeting a breakthrough in iCloud China workload.
A5: Is this request a part of cross service renewal? Please attach current cross service PPA and provide details on new cross service deal such as $ commit and CSD. | B5: Not a cross service renewal.
A6: What is underlying reason for private pricing or increased discounts on S3? | B6: Currently, iCloud is a key workload for which we have detailed information on the landscape. Based on the customer sponsor and our observations on Fruitstand's supply chain management, we need competitive pricing to win the opportunity for the share.
A7: What is the annual growth outlook for the customer (both on AWS and specifically on S3)? | B7: Fruitstand China currently have ARR 450K. There has only one workload, Great China Sales Training MyDemo from sales LoB using S3 with a ARR about 2K. After win the iCloud China opportunity, a 7M ARR would be a solid growth outlook for the customer.
A8: If the customer is not commiting to their expected usage or reducing commitment, please explain why is SCE aligned with the request. | B8: From iCloud China storage operation information, now the six vendors all have the commitment share with about 4 years contract from Fruitstand China. We don't think there would not have commitment.
A9: Is there a compete situation in the deal? If yes, who are we competing with and what visibility do we have on their offer? | B9: Currently 6 vendors had shared the capacity from Y2018. These 6 vendors are on two territories, #1 Telco, the major 3 Telco componies in China, China Mobile, China Telecom, China Unicom. #2 major China internet companies, Baidu, Ali and Tencent.
A10: What is the strategic importance of the requested S3/Glacier terms and what other S3 commits, service spend, workloads, or bargain can AWS (both storage and overall) stand to get if we approve these discounts? | B10: iCloud China capacity share and revenue.
A11: Is the customer willing to provide a public reference? | B11: We don't think so.
A12: Is the customer region flexible in terms of S3/Glacier usage? (specially DUB and SIN) Why not? | B12: Once confirm the region and kick off the ramp up, it would not be fexible to change the region.
A13: Please explain how are we working backwards from customer requested savings vs. a flat discount ask. Please attach TCO analyses or competetive financial comparisons done by SA/TAM or sales team. | B13: Target pricing was based on the competitor and customer's reference pricing benchmark.
... A15: What is the impact of not approving the requested discounts? | B15: We cannot open the door for negotiation with Fruitstand China for the share of the capacity. In 2025, there will be a renewal window with the current vendors by Fruitstnad China, and if we miss this window, there will not be opportunities for engagement for the next four years.

Sheet Additional Details
A1: Usage Storage Patterns
A2: For existing workloads with organic growth, we can use AWS data warehouse information to evaluate customer usage patterns. Additionally, if this is an existing customer but has new incoming workloads, can we use the current usage patterns (retrievals, DTO, etc)? If yes, skip line 4-13 | L2: NO
A3: For all other use cases, can you provide estimate on the below for each storage class in discussion?
A4: * Average object size and delete rate are critical inputs to a deal model. If actual numbers are not available, please input a range. For example - for object size, images are in the range of MBs, and video files are in the range of GBs. For delete rates, retrievals and data transfer - you can input low (0-10%), medium (10-25%) or high (>25%)
A5: Delete/GB stored on a monthly basis | L5: low
A6: Avg Object Size* | L6: 2.5MB
A7: What is the % of objects <70KB? | L7: N/A
A8: DataTransfer Out via internet / GB stored on a monthly basis (If DX is involved in data transfer, please refer to row 47) | L8: ='Data Ramp Plan'!I50 -> 0.005119125
A9: Retrievals / GB stored on a monthly basis | L9: ='Data Ramp Plan'!I51 -> 0.070353534
A10: EC2 -> S3 / GB stored on a monthly basis | L10: N/A
A11: S3 -> EC2 / GB stored on a monthly basis | L11: N/A
A12: Tier 1 Requests (PUT) / GB Stored - This refers to monthly Put requests/ total storage GB for that month | L12: ='Data Ramp Plan'!I48 -> 24.014006
A13: Tier 2 Requests (GET) / GB Stored - This refers to monthly GET requests/ total storage GB for that month | L13: ='Data Ramp Plan'!I49 -> 28.816807
A14: Does the customer use DX for data transfer (and not DTO via internet)? If yes, please give inputs below (mandatory for China region) | L14: No. Use DTI via Internet.
A16: Is DX/Snowball involved in data transfer? (Mandatory for China) | L16: NO
A17: Is there an existing DX PPA which will be applied on this storage deal private pricing along with transfer patterns as today? Will the same PPA terms be applied to the new deal? If yes, please attach the DX PPA and skip the below lines
A18: If answer to above in NO and DX is involved, request the account team or SA answer the below (for DX directly connected to S3 case only)
A19: Is the DX flat rate/dynamic pricing | L19: Input here
A20: If pricing is dynamic, please enter Port Hour discount and Data Transfer discounts | L20: Input here
A21: What is the % split between EC2 and S3 | L21: Input here
A22: Internet/DX split | L22: Input here
A23: Number of ports | L23: Input here
A24: Port Speed | L24: Input here
A25: Expected DTO Volume per Month | L25: Input here
A26: Expected DTI Volume per Month. | L26: Input here
A27: DX location/AWS Region to be accessed | L27: Input here

Sheet Dropdown inputs
A1: Regions
A2: select region | B2: select | C2: select | D2: select | E2: select | F2: select
A3: IAD | B3: YES | C3: AWS | D3: Linear | E3: Custom | F3: Within PARC, but custom due to term length
A4: DUB | B4: NO | C4: On-prem | D4: Non-Linear | E4: Within RC1 | F4: Inclusion of a non-PARC region
A5: SFO | C5: competition | E5: Within RC2 | F5: Within PARC, but custom due to other reasons
A6: SIN | E6: No discount but add towards commitment | F6: Not within PARC
A7: NRT
A8: PDT | B8: select | C8: select | D8: select | E8: select | F8: select
A9: PDX | B9: S3 Standard only | C9: SIA only | D9: GIR only | E9: GFR only | F9: GDA only
A10: GRU | B10: INT FA only | C10: INT IA only | D10: INT AIA only | E10: INT AA only | F10: INT DAA only
A11: SYD | B11: Both | C11: Both | D11: Both | E11: Both | F11: Both
A12: BJS
A13: DCA
A14: FRA
A15: ICN
A16: BOM
A17: CMH
A18: YUL
A19: LHR
A20: LCK
A21: ZHY
A22: CDG
A23: KIX
... A32: ZRH
